import pytest
from app.exceptions import UserNotFound


@pytest.mark.asyncio
async def test_delete_user_works_properly(user_service, valid_user_id):
    await user_service.delete_user(valid_user_id)
    assert valid_user_id not in user_service.profile_infos
    assert valid_user_id not in user_service.users_content


@pytest.mark.asyncio
async def test_delete_invalid_user_raises_proper_exception(user_service, invalid_user_delete_id):
    with pytest.raises(UserNotFound):
        await user_service.delete_user(invalid_user_delete_id)

# pytest tests -v
# pytest --cov=app tests/
# uvicorn main:app --reload
